Workbook

Sheet Overview
B4: Sustainability Category | C4: Directly available | D4: Indirectly available | E4: Extendable | F4: Not present | G4: Total
B5: Economic | C5: =GETPIVOTDATA("ID",Economic!$C$29,"SAP Status","directly available") -> 9 | D5: =GETPIVOTDATA("ID",Economic!$C$29,"SAP Status","indirectly available") -> 2 | E5: =GETPIVOTDATA("ID",Economic!$C$29,"SAP Status","extendable") -> 5 | F5: =GETPIVOTDATA("ID",Economic!$C$29,"SAP Status","not present") -> 5 | G5: =SUM(C5:F5) -> 21
B6: Environment | C6: 0 | D6: =GETPIVOTDATA("ID",Environment!$E$54,"SAP Status","indirectly available") -> 1 | E6: =GETPIVOTDATA("ID",Environment!$E$54,"SAP Status","extendable") -> 5 | F6: =GETPIVOTDATA("ID",Environment!$E$54,"SAP Status","not present") -> 40 | G6: =SUM(C6:F6) -> 46
B7: Social | C7: =GETPIVOTDATA("ID",Social!$D$69,"SAP Status","directly available") -> 4 | D7: =GETPIVOTDATA("ID",Social!$D$69,"SAP Status","indirectly available") -> 10 | E7: =GETPIVOTDATA("ID",Social!$D$69,"SAP Status","extendable") -> 18 | F7: =GETPIVOTDATA("ID",Social!$D$69,"SAP Status","not present") -> 29 | G7: =SUM(C7:F7) -> 61
B8: Governance | C8: =GETPIVOTDATA("ID",Governance!$D$24,"SAP Status","directly available") -> 2 | D8: =GETPIVOTDATA("ID",Governance!$D$24,"SAP Status","indirectly available") -> 2 | E8: 0 | F8: =GETPIVOTDATA("ID",Governance!$D$24,"SAP Status","not present") -> 12 | G8: =SUM(C8:F8) -> 16
B9: Total | C9: =SUM(C5:C8) -> 15 | D9: =SUM(D5:D8) -> 15 | E9: =SUM(E5:E8) -> 28 | F9: =SUM(F5:F8) -> 86 | G9: =SUM(C9:F9) -> 144
B10: Relative | C10: =C9/G9 -> 0.10416667 | D10: =D9/G9 -> 0.10416667 | E10: =E9/G9 -> 0.19444444 | F10: =F9/G9 -> 0.59722222
C11: =(C9+D9++E9)/G9 -> 0.40277778
E24: Zeilenbeschriftungen | F24: Sum Directly available | G24: Sum Indirectly available | H24: Sum Extendable | I24: Sum Not present
E25: Economic | F25: 9 | G25: 2 | H25: 5 | I25: 5
E26: Environment | F26: 0 | G26: 1 | H26: 5 | I26: 40
E27: Governance | F27: 2 | G27: 2 | H27: 0 | I27: 12
E28: Social | F28: 4 | G28: 10 | H28: 18 | I28: 29
E29: Gesamtergebnis | F29: 15 | G29: 15 | H29: 28 | I29: 86

Sheet Economic
A3: ID | B3: Category | C3: Process-Level Metric | D3: Source | E3: SAP Status | F3: SAP Location / Table | G3: Notes
A4: ="Econ" & ROW(A4) - 3 -> Econ1 | B4: Financial Performance | C4: Direct economic value generated: revenues | D4: GRI 201-1 | E4: directly available | F4: FI – Profit and Loss / Balance Sheet
A5: ="Econ" & ROW(A5) - 3 -> Econ2 | B5: Financial Performance | C5: Payments to providers of capital (Interest, Dividends) | D5: GRI 201-1 | E5: directly available | F5: FI – Accounts Payable
A6: ="Econ" & ROW(A6) - 3 -> Econ3 | B6: Taxes & Subsidies | C6: payments to government by country (Taxes) | D6: GRI 201-1 | E6: directly available | F6: BSET (tax data document segment) + PAYR (payment data table)
A7: ="Econ" & ROW(A7) - 3 -> Econ4 | B7: Social Contributions | C7: Community investments (Funds to support community infrastructure, Direct costs of social programs) | D7: GRI 201-1 | E7: extendable | F7: PRPS (project WBS elements) / AUFK (internal order master data) | G7: project / order information could be extended with social projects / intitiatives
A8: ="Econ" & ROW(A8) - 3 -> Econ5 | B8: Financial Performance | C8: Economic value retained: ‘direct economic value generated’ less ‘economic value distributed’ | D8: GRI 201-1 | E8: indirectly available | G8: can be calculated by subtracting total economic value distributed from total economic value generated
A9: ="Econ" & ROW(A9) - 3 -> Econ6 | B9: Financial Performance | C9: Energy Cost | D9: Wolf et al., 2025 | E9: directly available | F9: G/L Account 5190000 – Energy Materials (Production)
A10: ="Econ" & ROW(A10) - 3 -> Econ7 | B10: Financial Performance | C10: Disposal Cost | D10: Wolf et al., 2025 | E10: directly available | F10: ACDOCA (Universal Journal) - account 64600 (waste collection) / 64610 (special waste disposal) / 64620 (wastewater)
A11: ="Econ" & ROW(A11) - 3 -> Econ8 | B11: Financial Performance | C11: Extent of development of significant infrastructure investments and services supported | D11: GRI 203-1 | E11: extendable | F11: PRPS (project WBS elements) / AUFK (internal order master data) | G11: project / order information could be extended with infrastructure projects / intitiatives
A12: ="Econ" & ROW(A12) - 3 -> Econ9 | B12: Financial Performance | C12: Percentage of the procurement budget used for significant locations of operation that is spent on suppliers local to that operation (such as percentage of products and services purchased locally) | D12: GRI 204-1 | E12: indirectly available | F12: LFA1 (list of suppliers with locations) + EKKO (orders)
A13: ="Econ" & ROW(A13) - 3 -> Econ10 | B13: Environmental Expenditures | C13: Total expenditure on meeting environmental regulations | D13: Wolf et al., 2025 | E13: not present
A14: ="Econ" & ROW(A14) - 3 -> Econ11 | B14: Environmental Expenditures | C14: Total expenditure on proactive environmental initiatives | D14: Wolf et al., 2025 | E14: extendable | F14: PRPS (project WBS elements) / AUFK (internal order master data) | G14: project / order information could be extended with environment projects / orders
A15: ="Econ" & ROW(A15) - 3 -> Econ12 | B15: Social Contributions | C15: Personnel Costs | D15: Wolf et al., 2025 | E15: directly available | F15: G/L Account 8000000 – Labor / 8012000 – Production Wages Overhead
A16: ="Econ" & ROW(A16) - 3 -> Econ13 | B16: Social Contributions | C16: Defined benefit plan obligations and other retirement plans | D16: GRI 201-3 | E16: extendable | F16: T582A (customer-specific settings for infotypes) | G16: includes configuration possibility for Value of accrued occupational pension entitlement, but no implementation in current system
A17: ="Econ" & ROW(A17) - 3 -> Econ14 | B17: Social Contributions | C17: Total expenditure on employee training programs | D17: Wolf et al., 2025 | E17: directly available | F17: ACDOCA (Universal Journal) – Account 449400 (Services – Trainings) | G17: currently no associated entries
A18: ="Econ" & ROW(A18) - 3 -> Econ15 | B18: Environmental Expenditures | C18: Total savings from implementing environmental actions | D18: Wolf et al., 2025 | E18: not present
A19: ="Econ" & ROW(A19) - 3 -> Econ16 | B19: Social Contributions | C19: Total amount donated to charitable causes | D19: Wolf et al., 2025 | E19: directly available | F19: ACDOCA (Universal Journal) - accounts 65210 (Donations), 6390000 (Non-deductible donations), 6391000 (Donations to science & culture), 6394000 (Donations to political parties) | G19: currently no associated entries
A20: ="Econ" & ROW(A20) - 3 -> Econ17 | B20: Taxes & Subsidies | C20: Total monetary value of financial assistance received by the organization from any government during the reporting period | D20: GRI 201-4 | E20: directly available | F20: SKA1 (G/L account master) | G20: includes "subvention d'investi"
A21: ="Econ" & ROW(A21) - 3 -> Econ18 | B21: Environmental Expenditures | C21: Total expenditure on environmental actions and projects | D21: Wolf et al., 2025 | E21: extendable | F21: PRPS (project WBS elements) / AUFK (internal order master data) | G21: project / order information could be extended with environment projects / orders
A22: ="Econ" & ROW(A22) - 3 -> Econ19 | B22: Environmental Expenditures | C22: Total monetary return from environmental investments | D22: Wolf et al., 2025 | E22: not present
A23: ="Econ" & ROW(A23) - 3 -> Econ20 | B23: Environmental Expenditures | C23: Total additional revenue generated from sustainability actions | D23: Wolf et al., 2025 | E23: not present
A24: ="Econ" & ROW(A24) - 3 -> Econ21 | B24: Environmental Expenditures | C24: Number of environmental certifications owned | D24: Wolf et al., 2025 | E24: not present | G24: possibly existing within EHS extension
B26: Number Categories | C26: =COUNTA(_xlfn.UNIQUE(Tabelle1[Category])) -> 4
B27: Number Metrics | C27: =COUNTA(Tabelle1[Process-Level Metric]) -> 21
C29: Zeilenbeschriftungen | D29: Anzahl von ID
C30: directly available | D30: 9
C31: indirectly available | D31: 2
C32: extendable | D32: 5
C33: not present | D33: 5
C34: Gesamtergebnis | D34: 21

Sheet Environment
A3: ID | B3: Category | C3: Process-Level Metric | D3: Source | E3: SAP Status | F3: SAP Location | G3: Notes
A4: ="Env" & ROW(A4) - 3 -> Env1 | B4: Energy | C4: Total amount of energy used | D4: Wolf et al., 2025 | E4: not present
A5: ="Env" & ROW(A5) - 3 -> Env2 | B5: Energy | C5: Total amount of renewable energy used | D5: Wolf et al., 2025 | E5: not present
A6: ="Env" & ROW(A6) - 3 -> Env3 | B6: Energy | C6: Total amount of energy recovered and reused | D6: Wolf et al., 2025 | E6: not present
A7: ="Env" & ROW(A7) - 3 -> Env4 | B7: Energy | C7: Reductions in energy requirements of sold products and services achieved during the reporting period | D7: GRI 302-5 | E7: not present | G7: possibly existing within PLM extension
A8: ="Env" & ROW(A8) - 3 -> Env5 | B8: Energy | C8: Energy Efficiency | D8: Wolf et al., 2025 | E8: not present
A9: ="Env" & ROW(A9) - 3 -> Env6 | B9: Energy | C9: Energy intensity (total energy consumption per net revenue) associated with activities in high climate impact sectors | D9: ESRS DR E1-5 | E9: not present
A10: ="Env" & ROW(A10) - 3 -> Env7 | B10: Energy | C10: Total amount of gas used | D10: Wolf et al., 2025 | E10: not present
A11: ="Env" & ROW(A11) - 3 -> Env8 | B11: Energy | C11: Total amount of fuel used | D11: Wolf et al., 2025 | E11: not present
A12: ="Env" & ROW(A12) - 3 -> Env9 | B12: Material | C12: Total amount of material recycled | D12: Wolf et al., 2025 | E12: not present
A13: ="Env" & ROW(A13) - 3 -> Env10 | B13: Material | C13: Total amount of material reused | D13: Wolf et al., 2025 | E13: not present
A14: ="Env" & ROW(A14) - 3 -> Env11 | B14: Material | C14: Total amount of material remanufactured | D14: Wolf et al., 2025 | E14: not present
A15: ="Env" & ROW(A15) - 3 -> Env12 | B15: Material | C15: the total weight (tonnes) and percentage of materials that come out of the undertaking’s products and services production process (including packaging) that have been designed along circular principles (specified in DR E5-5) | D15: ESRS DR E5-5 | E15: not present
A16: ="Env" & ROW(A16) - 3 -> Env13 | B16: Material | C16: weight and percentage of products and materials that come out of the undertaking including packaging that are designed to enhance/enable circular economy for customers further down the value chain | D16: ESRS DR E5-5 | E16: not present | G16: possibly existing within PLM extension
A17: ="Env" & ROW(A17) - 3 -> Env14 | B17: Material | C17: Total amount of renewable material used | D17: Wolf et al., 2025 | E17: extendable | F17: MARA (general material master data) - "Material" | G17: include information on material sustainability type
A18: ="Env" & ROW(A18) - 3 -> Env15 | B18: Material | C18: Total amount of virgin material used | D18: Wolf et al., 2025 | E18: extendable | F18: MARA (general material master data) - "Material" | G18: include information on material sustainability type
A19: ="Env" & ROW(A19) - 3 -> Env16 | B19: Material | C19: Total amount of compostable material used | D19: Wolf et al., 2025 | E19: extendable | F19: MARA (general material master data) - "Material" | G19: include information on material sustainability type
A20: ="Env" & ROW(A20) - 3 -> Env17 | B20: Material | C20: Total amount of material consumed | D20: Wolf et al., 2025 | E20: indirectly available | F20: MARA (general material master data) - "Bruttogewicht" / Gross Weight + MSEG (Material document segment) | G20: can be calculated using the material weight specified in MARA and the material movement specified in MSEG
A21: ="Env" & ROW(A21) - 3 -> Env18 | B21: Material | C21: Ratio of useful material output to total material input | D21: Wolf et al., 2025 | E21: not present
A22: ="Env" & ROW(A22) - 3 -> Env19 | B22: Material | C22: Total amount of hazardous substances use | D22: Wolf et al., 2025 | E22: not present
A23: ="Env" & ROW(A23) - 3 -> Env20 | B23: Material | C23: Total amount of paper used | D23: Wolf et al., 2025 | E23: extendable | F23: MARA (general material master data) - "Verpackungsmaterial" / packaging material | G23: currently only include general information on packaging type
A24: ="Env" & ROW(A24) - 3 -> Env21 | B24: Waste | C24: Total amount of waste produced | D24: Wolf et al., 2025 | E24: not present
A25: ="Env" & ROW(A25) - 3 -> Env22 | B25: Waste | C25: Materials that are present in the waste (e.g., biomass, metals, non-metallic minerals, plastics, textiles) | D25: ESRS DR E5-5 | E25: not present
A26: ="Env" & ROW(A26) - 3 -> Env23 | B26: Waste | C26: Total amount of waste processed for recycling | D26: Wolf et al., 2025 | E26: not present
A27: ="Env" & ROW(A27) - 3 -> Env24 | B27: Waste | C27: Total amount of solid waste produced | D27: Wolf et al., 2025 | E27: not present
A28: ="Env" & ROW(A28) - 3 -> Env25 | B28: Waste | C28: Total amount of waste redirected from landfill | D28: Wolf et al., 2025 | E28: not present
A29: ="Env" & ROW(A29) - 3 -> Env26 | B29: Waste | C29: for each type of hazardous and non-hazardous waste, the amount by weight directed to disposal by waste treatment type | D29: ESRS DR E5-5 | E29: not present
A30: ="Env" & ROW(A30) - 3 -> Env27 | B30: Waste | C30: Total amount of hazardous waste produced | D30: Wolf et al., 2025 | E30: not present
A31: ="Env" & ROW(A31) - 3 -> Env28 | B31: Emissions | C31: Total amount of CO2 emitted | D31: Wolf et al., 2025 | E31: not present
A32: ="Env" & ROW(A32) - 3 -> Env29 | B32: Emissions | C32: Total amount of other greenhouse gases emitted | D32: Wolf et al., 2025 | E32: not present
A33: ="Env" & ROW(A33) - 3 -> Env30 | B33: Emissions | C33: Total amount of gases emitted | D33: Wolf et al., 2025 | E33: not present
A34: ="Env" & ROW(A34) - 3 -> Env31 | B34: Emissions | C34: GHG removals and storage from its own operations and its upstream and downstream value chain | D34: ESRS DR E1-7 | E34: not present
A35: ="Env" & ROW(A35) - 3 -> Env32 | B35: Emissions | C35: Carbon credits the undertaking has purchased from the voluntary market and cancelled in the reporting period | D35: ESRS DR E1-7 | E35: not present
A36: ="Env" & ROW(A36) - 3 -> Env33 | B36: Emissions | C36: Carbon prices applied according to the type of scheme and critical assumptions made to determine the prices | D36: ESRS DR E1-8 | E36: not present
A37: ="Env" & ROW(A37) - 3 -> Env34 | B37: Emissions | C37: Total amount of ozone-depleting gases emitted | D37: Wolf et al., 2025 | E37: not present | G37: possibly existing within EHS extension
A38: ="Env" & ROW(A38) - 3 -> Env35 | B38: Emissions | C38: Total amount of pollutants emitted into the air | D38: Wolf et al., 2025 | E38: not present | G38: possibly existing within EHS extension
A39: ="Env" & ROW(A39) - 3 -> Env36 | B39: Land and Water | C39: Total amount of pollutants emitted onto land | D39: Wolf et al., 2025 | E39: not present | G39: possibly existing within EHS extension
A40: ="Env" & ROW(A40) - 3 -> Env37 | B40: Land and Water | C40: Total amount of pollutants emitted into water | D40: Wolf et al., 2025 | E40: not present | G40: possibly existing within EHS extension
A41: ="Env" & ROW(A41) - 3 -> Env38 | B41: Emissions | C41: Rate of radiation emitted | D41: Wolf et al., 2025 | E41: not present | G41: possibly existing within EHS extension
A42: ="Env" & ROW(A42) - 3 -> Env39 | B42: Land and Water | C42: Number and area (in hectares) of sites owned, leased or managed in or near these protected areas or key biodiversity areas | D42: ESRS DR E4-5 | E42: extendable | F42: T001W (Plant data) | G42: plant data could be extended with area information; exisiting location information can be used to calculate proximity to protected and key biodiversity areas
...

Sheet Social
A3: ID | B3: Category | C3: Process-Level Metric | D3: Source | E3: SAP Status | F3: SAP Location | G3: Notes
A4: ="Soc" & ROW(A4) - 3 -> Soc1 | B4: Stakeholder Satisfaction | C4: Percentage of stakeholders who are content with the business processes | D4: Wolf et al., 2025 | E4: extendable | G4: see Soc1 + Soc2 for subcategory satisfaction rates; could include other dimensions as well
A5: ="Soc" & ROW(A5) - 3 -> Soc2 | B5: Stakeholder Satisfaction | C5: Percentage of customers who are content with the products or services | D5: Wolf et al., 2025 | E5: extendable | F5: KNVV (Customer Master Sales Data) | G5: could be extended with information from surveys, complaints or other feedback channels
A6: ="Soc" & ROW(A6) - 3 -> Soc3 | B6: Stakeholder Satisfaction | C6: Percentage of employees who are content with the work environment | D6: Wolf et al., 2025 | E6: extendable | F6: PA0002 (HR - staff data) | G6: could be extended with information from surveys, complaints or other feedback channels
A7: ="Soc" & ROW(A7) - 3 -> Soc4 | B7: Stakeholder Satisfaction | C7: Percentage of local community members content with the business’ impact on the community | D7: Wolf et al., 2025 | E7: not present
A8: ="Soc" & ROW(A8) - 3 -> Soc5 | B8: Stakeholder Satisfaction | C8: Total number of substantiated complaints received concerning breaches of customer privacy | D8: GRI 418-1 | E8: extendable | F8: QMEL (Quality Management Notifications) | G8: typically includes information on operational and technical incidencts such as incidents related to technical equiment and plant maintanance; could be extended to data privacy
A9: ="Soc" & ROW(A9) - 3 -> Soc6 | B9: Stakeholder Satisfaction | C9: Total number of identified leaks, thefts, or losses of customer data | D9: GRI 418-1 | E9: extendable | F9: QMEL (Quality Management Notifications) | G9: typically includes information on operational and technical incidencts such as incidents related to technical equiment and plant maintanance; could be extended to data privacy
A10: ="Soc" & ROW(A10) - 3 -> Soc7 | B10: Employee Health & Safety | C10: Number of cases of recordable work-related ill health | D10: ESRS DR S1-14 | E10: extendable | F10: T554S (Absence Types) | G10: includes category for work-related illness
A11: ="Soc" & ROW(A11) - 3 -> Soc8 | B11: Employee Health & Safety | C11: Percentage of significant product and service categories for which health and safety impacts are assessed for improvement | D11: GRI 416-1 | E11: not present | G11: possibly existing within EHS Extension
A12: ="Soc" & ROW(A12) - 3 -> Soc9 | B12: Employee Health & Safety | C12: Count of accidents or incidents that occur in a business activity | D12: Wolf et al., 2025 | E12: extendable | F12: T554S (Absence Types) | G12: includes Absence type "workplace accident"
A13: ="Soc" & ROW(A13) - 3 -> Soc10 | B13: Employee Health & Safety | C13: The number and rate of recordable work-related injuries | D13: GRI 403-9 | E13: extendable | F13: T554S (Absence Types) | G13: includes Absence type for work-related accidents, but no absence table existing in current system
A14: ="Soc" & ROW(A14) - 3 -> Soc11 | B14: Employee Health & Safety | C14: The number and rate of fatalities as a result of work-related injury + The number of fatalities as a result of work-related ill health | D14: GRI 403-9 + GRI 403-10 | E14: not present | G14: possibly existing within EHS Extension
A15: ="Soc" & ROW(A15) - 3 -> Soc12 | B15: Employee Health & Safety | C15: The number and rate of high-consequence work-related injuries (excluding fatalities) | D15: GRI 403-9 | E15: not present | G15: possibly existing within EHS Extension
A16: ="Soc" & ROW(A16) - 3 -> Soc13 | B16: Employee Health & Safety | C16: Number of fatalities as result of work-related injuries and work-related ill health of other workers working on undertaking's sites | D16: ESRS DR S1-16 | E16: not present | G16: possibly existing within EHS Extension
A17: ="Soc" & ROW(A17) - 3 -> Soc14 | B17: Employee Health & Safety | C17: Number of days employees are absent due to illness | D17: Wolf et al., 2025 | E17: directly available | F17: PA0050 (HR - time tracking) | G17: currently no entries
A18: ="Soc" & ROW(A18) - 3 -> Soc15 | B18: Employee Health & Safety | C18: Number of workdays employees are absent due to injuries sustained from work-related accidents | D18: Wolf et al., 2025 | E18: extendable | F18: T554S (Absence Types) | G18: includes category for work-related accidents, but no absence table existing in current system
A19: ="Soc" & ROW(A19) - 3 -> Soc16 | B19: Employee Health & Safety | C19: The number of hours worked | D19: GRI 403-9 | E19: directly available | F19: PA0007 (HR - working hours) / PA0050 (HR - time tracking) | G19: currently no entries
A20: ="Soc" & ROW(A20) - 3 -> Soc17 | B20: Employee Health & Safety | C20: Percentage of own workers who are covered by the undertaking’s health and safety management system | D20: ESRS DR S1-14 | E20: not present
A21: ="Soc" & ROW(A21) - 3 -> Soc18 | B21: Employee Health & Safety | C21: Percentage of employees entitled to take family-related leaves | D21: ESRS DR S1-14 | E21: not present
A22: ="Soc" & ROW(A22) - 3 -> Soc19 | B22: Employee Health & Safety | C22: Percentage of entitled employees that took family-related leave | D22: ESRS DR S1-14 | E22: extendable | F22: T554S (Absence Types) | G22: includes absence type for parental leave
A23: ="Soc" & ROW(A23) - 3 -> Soc20 | B23: Employee Health & Safety | C23: Total number of employees that returned to work in the reporting period after parental leave ended, by gender | D23: GRI 401-3 | E23: extendable | F23: T554S (Absence Types) | G23: includes absence type for parental leave; could be used for further calculation
A24: ="Soc" & ROW(A24) - 3 -> Soc21 | B24: Employee Health & Safety | C24: Return to work and retention rates of employees that took parental leave, by gender | D24: GRI 401-3 | E24: extendable | F24: T554S (Absence Types) | G24: includes absence type for parental leave; could be used for further calculation
A25: ="Soc" & ROW(A25) - 3 -> Soc22 | B25: Employee Health & Safety | C25: Minimum number of weeks’ notice typically provided to employees and their representatives prior to the implementation of significant operational changes that could substantially affect them | D25: GRI 402-1 | E25: not present | G25: includes configuration options for notice periodes for termination (T547T) but no other information
A26: ="Soc" & ROW(A26) - 3 -> Soc23 | B26: Employee Health & Safety | C26: Number of actions or tasks that can potentially introduce risks or uncertainties | D26: Wolf et al., 2025 | E26: not present
A27: ="Soc" & ROW(A27) - 3 -> Soc24 | B27: Employee Health & Safety | C27: Number of actions to encourage and maintain employee health and well-being | D27: Wolf et al., 2025 | E27: not present
A28: ="Soc" & ROW(A28) - 3 -> Soc25 | B28: Employee Health & Safety | C28: Percentage of employees exposed to harmful chemicals in the workplace | D28: Wolf et al., 2025 | E28: not present
A29: ="Soc" & ROW(A29) - 3 -> Soc26 | B29: Employee Health & Safety | C29: Amount of particulate matter present in the air at specific working location | D29: Wolf et al., 2025 | E29: not present
A30: ="Soc" & ROW(A30) - 3 -> Soc27 | B30: Employee Health & Safety | C30: Sound level at a specific working location | D30: Wolf et al., 2025 | E30: not present
A31: ="Soc" & ROW(A31) - 3 -> Soc28 | B31: Employee Health & Safety | C31: Intensity of periodic oscillations at a working station caused by machines, tools, or other equipment | D31: Wolf et al., 2025 | E31: not present
A32: ="Soc" & ROW(A32) - 3 -> Soc29 | B32: Employee Development & Compensation | C32: Number of training hours completed by employees | D32: Wolf et al., 2025 | E32: not present | G32: no training information within current system; possibly existing within Success Factors / LMS
A33: ="Soc" & ROW(A33) - 3 -> Soc30 | B33: Employee Development & Compensation | C33: Percentage of employees that participated in regular performance and career development reviews | D33: ESRS DR S1-13 | E33: not present | G33: possibly existing within Success Factors
A34: ="Soc" & ROW(A34) - 3 -> Soc31 | B34: Employee Development & Compensation | C34: Skill level of employees | D34: Wolf et al., 2025 | E34: extendable | F34: T503K (employee subgroup) / PA0001 (Organizational Assignment) | G34: includes information on employee grouping / rank; possibly directly existing within Success Factors / LMS
A35: ="Soc" & ROW(A35) - 3 -> Soc32 | B35: Employee Development & Compensation | C35: Number of benefits and rewards offered to employees | D35: Wolf et al., 2025 | E35: not present
A36: ="Soc" & ROW(A36) - 3 -> Soc33 | B36: Employee Rights & Diversity | C36: Total number and rate of new employee hires during the reporting period, by age group, gender and region | D36: GRI 401-1 | E36: directly available | F36: PA0000 (HR - actions) | G36: includes action for new staffing, can be used for further calculation
A37: ="Soc" & ROW(A37) - 3 -> Soc34 | B37: Employee Rights & Diversity | C37: Ratio of productive work hours to the total work hours of employees | D37: Wolf et al., 2025 | E37: indirectly available | F37: PA0050 (HR - time tracking) + PA0007 (HR - working time) | G37: can be calculated be comparing actual working time and planned working time
A38: ="Soc" & ROW(A38) - 3 -> Soc35 | B38: Employee Rights & Diversity | C38: Ratio of employees who leave to the total number of employees | D38: Wolf et al., 2025 | E38: indirectly available | F38: PA0000 (HR - actions) | G38: includes action for staff exists, can be used for ratio calculation
A39: ="Soc" & ROW(A39) - 3 -> Soc36 | B39: Employee Rights & Diversity | C39: Ratio of male to female employees | D39: Wolf et al., 2025 | E39: indirectly available | F39: PA0002 (HR - staff data) | G39: includes column for gender, can be used for ratio calculation
A40: ="Soc" & ROW(A40) - 3 -> Soc37 | B40: Employee Rights & Diversity | C40: Gender Distribution at top management level | D40: ESRS DR S1-9 | E40: indirectly available | F40: PA0002 (HR - staff data) | G40: filter by top-level management employees and use gender column
A41: ="Soc" & ROW(A41) - 3 -> Soc38 | B41: Employee Development & Compensation | C41: Gender pay gap | D41: ESRS DR S1-16 | E41: indirectly available | F41: ACDOCA (Universal Journal) - accounts 8000000 - Workforce / 8012000 - Production Loans + PA0002 (HR - staff data) | G41: includes information on saleries, can be used for calculating gender pay gap togehter with gender information within HR staff data
A42: ="Soc" & ROW(A42) - 3 -> Soc39 | B42: Employee Development & Compensation | C42: Ratio of the annual total compensation ratio of the highest paid individual to the median annual total compensation for all employees | D42: ESRS DR S1-16 | E42: indirectly available | F42: G/L Account 8000000 – Labor / 8012000 – Production Wages Overhead
...

Sheet Governance
A3: ID | B3: Category | C3: Process-Level Metric | D3: Source | E3: SAP Status | F3: SAP Location | G3: Notes
A4: ="Gov" & ROW(A4) - 3 -> Gov1 | B4: Payment Compliance | C4: Average invoice payment duration | D4: ESRS DR G1-6 | E4: indirectly available | F4: BSEG (Accounting Document Segment) + PAYR (payment data table) | G4: can be calculated using invoice posting date from BSEG and payment date from PAYR
A5: ="Gov" & ROW(A5) - 3 -> Gov2 | B5: Payment Compliance | C5: Standard Payment Terms Compliance | D5: ESRS DR G1-6 | E5: indirectly available | F5: EKKO (Purchasing Document Header) + T052 (Terms of Payment) + PAYR (payment data table) | G5: can be calculated using the standard payment terms and actual payment durations
A6: ="Gov" & ROW(A6) - 3 -> Gov3 | B6: Legal Compliance | C6: Total number of incidents of non-compliance with regulations and/or voluntary codes concerning the health and safety impacts of products and services within the reporting period | D6: GRI 416-2 | E6: not present | G6: possibly existing within EHS Extension
A7: ="Gov" & ROW(A7) - 3 -> Gov4 | B7: Legal Compliance | C7: Total number of incidents of non-compliance with regulations and/or voluntary codes concerning product and service information and labeling | D7: GRI 417-2 | E7: not present | G7: possibly existing within EHS Extension
A8: ="Gov" & ROW(A8) - 3 -> Gov5 | B8: Legal Compliance | C8: Total number of incidents of non-compliance with regulations and/or voluntary codes concerning marketing communications, including advertising, promotion, and sponsorship | D8: GRI 417-3 | E8: not present | G8: possibly existing within EHS Extension
A9: ="Gov" & ROW(A9) - 3 -> Gov6 | B9: Corruption & Fraud | C9: Public legal cases regarding corruption brought against the organization or ist employees during the reporting period and the outcomes of such cases. | D9: GRI 205-3 | E9: not present | G9: possibly existing within GRC Extension
A10: ="Gov" & ROW(A10) - 3 -> Gov7 | B10: Corruption & Fraud | C10: Number of legal actions pending or completed during the reporting period regarding anti-competitive behavior and violations of anti-trust and monopoly legislation in which the organization has been identified as a participant | D10: GRI 206-1 | E10: not present | G10: possibly existing within GRC Extension
A11: ="Gov" & ROW(A11) - 3 -> Gov8 | B11: Corruption & Fraud | C11: Total number and percentage of operations assessed for risks related to corruption | D11: GRI 205-1 | E11: not present | G11: possibly existing within GRC Extension
A12: ="Gov" & ROW(A12) - 3 -> Gov9 | B12: Corruption & Fraud | C12: Total number and nature of confirmed incidents of corruption | D12: GRI 205-3 | E12: not present | G12: possibly existing within GRC Extension
A13: ="Gov" & ROW(A13) - 3 -> Gov10 | B13: Corruption & Fraud | C13: Public legal cases regarding corruption brought against the organization or ist employees during the reporting period and the outcomes of such cases. | D13: GRI 205-3 | E13: not present | G13: possibly existing within GRC Extension
A14: ="Gov" & ROW(A14) - 3 -> Gov11 | B14: Corruption & Fraud | C14: Significant fines and non-monetary sanctions for non-compliance with laws and/or regulations in the social and economic area | D14: GRI 419-1 | E14: directly available | F14: ACDOCA (Universal Journal) - account 644000 (Contractual & Delay Fines) / 645000 (Other Fines)
A15: ="Gov" & ROW(A15) - 3 -> Gov12 | B15: Corruption & Fraud | C15: Process Outcomes (Corruption or Bribery) | D15: DR G1-4 | E15: not present | G15: no training-related information stored in current system; possibly existing within Success Factors / LMS
A16: ="Gov" & ROW(A16) - 3 -> Gov13 | B16: Corruption & Fraud | C16: Total number and percentage of employees that have received training on anti-corruption, broken down by employee category and region | D16: GRI 205-2 | E16: not present | G16: possibly existing within Success Factors / LMS / GRC
A17: ="Gov" & ROW(A17) - 3 -> Gov14 | B17: Corruption & Fraud | C17: Duration of classroom training (hours) / computer-based training of anti-corruption training | D17: ESRS DR G1-3 | E17: not present | G17: possibly existing within Success Factors / LMS / GRC
A18: ="Gov" & ROW(A18) - 3 -> Gov15 | B18: Corruption & Fraud | C18: Total number and percentage of governance body members that the organization’s anti-corruption policies and procedures have been communicated to | D18: GRI 205-2 | E18: not present | G18: possibly existing within Success Factors / LMS / GRC
A19: ="Gov" & ROW(A19) - 3 -> Gov16 | B19: Corruption & Fraud | C19: Total monetary value of financial and in-kind political contributions made directly and indirectly by the organization by country and recipient/beneficiary | D19: GRI 415-1 | E19: directly available | F19: ACDOCA (Universal Journal) - account 6394000 (political donations) | G19: currently no associated entries
B22: Number Categories | C22: =COUNTA(_xlfn.UNIQUE(Tabelle4[Category])) -> 3
B23: Number Metrics | C23: =COUNTA(Tabelle4[Process-Level Metric]) -> 16
D24: Zeilenbeschriftungen | E24: Anzahl von ID
D25: directly available | E25: 2
D26: indirectly available | E26: 2
D27: not present | E27: 12
D28: Gesamtergebnis | E28: 16
